<?xml version="1.0" ?>
<robot name="stretch_description" version="1.0">
  <link name="link_wrist_yaw_bottom">
    <inertial>
      <origin xyz="-0.012839101377342 -0.0382787718640742 -0.0228400332263617" rpy="0.0 0.0 0.0"/>
      <mass value="0.0988906816399982"/>
      <inertia ixx="2.60067866573596e-05" ixy="-6.73176267521354e-06" ixz="-2.43476436723672e-06" iyy="5.99482946819923e-06" iyz="-3.39642410492401e-06" izz="2.56907114334732e-05"/>
    </inertial>
    <visual>
      <origin xyz="0.0 0.0 0.0" rpy="0.0 0.0 0.0"/>
      <geometry>
        <mesh filename="../meshes/link_wrist_yaw_bottom.STL"/>
      </geometry>
      <material name="">
        <color rgba="0.792156862745098 0.819607843137255 0.933333333333333 1.0"/>
      </material>
    </visual>
    <collision>
      <origin xyz="-0.013291 -0.0214 -0.02075" rpy="1.570796 1.570796 0.0"/>
      <geometry>
        <box size="0.0415 0.062919 0.0943"/>
      </geometry>
    </collision>
  </link>
  <joint name="joint_wrist_yaw_bottom" type="fixed">
    <origin xyz="0.0 0.0 0.0" rpy="-3.14159265358979 1.13367999021379e-14 1.57079632679489"/>
    <axis xyz="0.0 0.0 0.0"/>
    <parent link="link_wrist_yaw"/>
    <child link="link_wrist_yaw_bottom"/>
  </joint>
  <link name="link_wrist_pitch">
    <inertial>
      <origin xyz="-0.00310609611067142 -0.0150777141465843 0.0204734587925901" rpy="0.0 0.0 0.0"/>
      <mass value="0.0701267146295583"/>
      <inertia ixx="2.55965614980905e-06" ixy="-1.47551515167608e-06" ixz="-6.31436085977252e-08" iyy="3.43968637386282e-06" iyz="-4.17813567208843e-07" izz="4.53568668211393e-06"/>
    </inertial>
    <visual>
      <origin xyz="0.0 0.0 0.0" rpy="0.0 0.0 0.0"/>
      <geometry>
        <mesh filename="../meshes/link_wrist_pitch.STL"/>
      </geometry>
      <material name="">
        <color rgba="0.792156862745098 0.819607843137255 0.933333333333333 1.0"/>
      </material>
    </visual>
    <collision>
      <origin xyz="-0.006179 -0.012056 0.020731" rpy="1.570796 1.570796 0.0"/>
      <geometry>
        <box size="0.043138 0.053359 0.064888"/>
      </geometry>
    </collision>
  </link>
  <joint name="joint_wrist_pitch" type="revolute">
    <origin xyz="0.0 -0.0195500000000002 -0.0247499999999984" rpy="1.5707963267949 -8.12895570882604e-15 -3.14159265358979"/>
    <axis xyz="0.0 0.0 -1.0"/>
    <parent link="link_wrist_yaw_bottom"/>
    <child link="link_wrist_pitch"/>
    <limit effort="100.0" lower="-1.57" upper="0.56" velocity="1.0"/>
  </joint>
  <link name="link_wrist_roll">
    <inertial>
      <origin xyz="9.63118473862323e-15 -6.38378239159465e-15 0.00768048802649798" rpy="0.0 0.0 0.0"/>
      <mass value="0.00585666394358811"/>
      <inertia ixx="2.55965614980905e-06" ixy="-1.47551515167608e-06" ixz="-6.31436085977252e-08" iyy="3.43968637386282e-06" iyz="-4.17813567208843e-07" izz="4.53568668211393e-06"/>
    </inertial>
    <visual>
      <origin xyz="0.0 0.0 0.0" rpy="0.0 0.0 0.0"/>
      <geometry>
        <mesh filename="../meshes/link_wrist_roll.STL"/>
      </geometry>
      <material name="">
        <color rgba="0.792156862745098 0.819607843137255 0.933333333333333 1.0"/>
      </material>
    </visual>
    <collision>
      <origin xyz="-0.0 -0.0 0.00775" rpy="-1.15743 1.570796 0.0"/>
      <geometry>
        <box size="0.0155 0.028888 0.028987"/>
      </geometry>
    </collision>
  </link>
  <joint name="joint_wrist_roll" type="revolute">
    <origin xyz="-0.0188587444076125 -0.0239999999998942 0.01955" rpy="3.14159265358979 1.5707963267949 0.0"/>
    <axis xyz="0.0 0.0 1.0"/>
    <parent link="link_wrist_pitch"/>
    <child link="link_wrist_roll"/>
    <limit effort="100.0" lower="-3.14" upper="3.14" velocity="1.0"/>
  </joint>
  <link name="link_straight_gripper">
    <inertial>
      <origin xyz="0.00150764845432383 -0.00711581846201287 0.0399737901417758" rpy="0.0 0.0 0.0"/>
      <mass value="0.0496384234458284"/>
      <inertia ixx="5.61461154156397e-06" ixy="8.29518962984231e-07" ixz="-2.41382921888194e-06" iyy="1.11504692003467e-05" iyz="9.76174898123369e-07" izz="6.63803357903882e-06"/>
    </inertial>
    <visual>
      <origin xyz="0.0 0.0 0.0" rpy="0.0 0.0 0.0"/>
      <geometry>
        <mesh filename="../meshes/link_straight_gripper.STL"/>
      </geometry>
      <material name="">
        <color rgba="0.792156862745098 0.819607843137255 0.933333333333333 1.0"/>
      </material>
    </visual>
    <collision>
      <origin xyz="-0.0 -0.013998 0.054277" rpy="0.010085 0.0 3.141593"/>
      <geometry>
        <box size="0.052858 0.056076 0.108538"/>
      </geometry>
    </collision>
  </link>
  <joint name="joint_straight_gripper" type="fixed">
    <origin xyz="0.0 0.0 0.0155" rpy="3.54987407349455e-30 3.24021254484265e-20 -3.14159265358979"/>
    <axis xyz="0.0 0.0 0.0"/>
    <parent link="link_wrist_roll"/>
    <child link="link_straight_gripper"/>
  </joint>
  <link name="link_gripper_finger_right">
    <inertial>
      <origin xyz="-0.094981 -0.0080152 -2.2204e-16" rpy="0.0 0.0 0.0"/>
      <mass value="0.047621"/>
      <inertia ixx="0.001" ixy="0.0" ixz="0.0" iyy="0.001" iyz="0.0" izz="0.001"/>
    </inertial>
    <visual>
      <origin xyz="0.0 0.0 0.0" rpy="0.0 0.0 0.0"/>
      <geometry>
        <mesh filename="../meshes/link_gripper_finger_right.STL"/>
      </geometry>
      <material name="">
        <color rgba="0.79216 0.81961 0.93333 1.0"/>
      </material>
    </visual>
    <collision>
      <origin xyz="-0.097587 -0.0146 0.0" rpy="-0.063447 1.570796 0.0"/>
      <geometry>
        <box size="0.013 0.03021 0.196835"/>
      </geometry>
    </collision>
  </link>
  <joint name="joint_gripper_finger_right" type="revolute">
    <origin xyz="-0.018599 0.003 0.033689" rpy="1.5708 1.5708 0.0"/>
    <axis xyz="0.0 0.0 1.0"/>
    <parent link="link_straight_gripper"/>
    <child link="link_gripper_finger_right"/>
    <limit effort="100.0" lower="-0.6" upper="0.6" velocity="1.0"/>
  </joint>
  <link name="link_gripper_fingertip_right">
    <inertial>
      <origin xyz="2.83785970833783e-08 6.75131661687089e-09 0.00812578923434215" rpy="0.0 0.0 0.0"/>
      <mass value="0.00382160881468841"/>
      <inertia ixx="0.001" ixy="0.0" ixz="0.0" iyy="0.001" iyz="0.0" izz="0.001"/>
    </inertial>
    <visual>
      <origin xyz="0.0 0.0 0.0" rpy="0.0 0.0 0.0"/>
      <geometry>
        <mesh filename="../meshes/link_gripper_fingertip_right.STL"/>
      </geometry>
      <material name="">
        <color rgba="0.250980392156863 0.250980392156863 0.250980392156863 1.0"/>
      </material>
    </visual>
    <collision>
      <origin xyz="0.0 0.0 0.0" rpy="0.0 0.0 0.0"/>
      <geometry>
        <mesh filename="../meshes/link_gripper_fingertip_right.STL"/>
      </geometry>
    </collision>
  </link>
  <joint name="joint_gripper_fingertip_right" type="fixed">
    <origin xyz="-0.190596948563868 -0.015 0.0" rpy="-1.57079632679483 -3.43320051448326e-14 0.540456056432235"/>
    <axis xyz="0.0 0.0 0.0"/>
    <parent link="link_gripper_finger_right"/>
    <child link="link_gripper_fingertip_right"/>
  </joint>
  <link name="link_gripper_finger_left">
    <inertial>
      <origin xyz="0.0949811095686165 -0.00801522758203194 1.38777878078145e-15" rpy="0.0 0.0 0.0"/>
      <mass value="0.0476207785199479"/>
      <inertia ixx="0.001" ixy="0.0" ixz="0.0" iyy="0.001" iyz="0.0" izz="0.001"/>
    </inertial>
    <visual>
      <origin xyz="0.0 0.0 0.0" rpy="3.141592653589793 0.0 0.0"/>
      <geometry>
        <mesh filename="../meshes/link_gripper_finger_left.STL"/>
      </geometry>
      <material name="">
        <color rgba="0.792156862745098 0.819607843137255 0.933333333333333 1.0"/>
      </material>
    </visual>
    <collision>
      <origin xyz="0.097587 0.0146 0.0" rpy="3.078145 1.570796 0.0"/>
      <geometry>
        <box size="0.013 0.03021 0.196835"/>
      </geometry>
    </collision>
  </link>
  <joint name="joint_gripper_finger_left" type="revolute">
    <origin xyz="0.018599 0.003 0.033689" rpy="1.5708 -1.5708 0.0"/>
    <axis xyz="0.0 0.0 -1.0"/>
    <parent link="link_straight_gripper"/>
    <child link="link_gripper_finger_left"/>
    <limit effort="100.0" lower="-0.6" upper="0.6" velocity="1.0"/>
  </joint>
  <link name="link_gripper_fingertip_left">
    <inertial>
      <origin xyz="-2.59496317767116e-08 -6.65612598371723e-09 0.00812579036862837" rpy="0.0 0.0 0.0"/>
      <mass value="0.00382160686584851"/>
      <inertia ixx="0.001" ixy="0.0" ixz="0.0" iyy="0.001" iyz="0.0" izz="0.001"/>
    </inertial>
    <visual>
      <origin xyz="0.0 0.0 0.0" rpy="0.0 0.0 0.0"/>
      <geometry>
        <mesh filename="../meshes/link_gripper_fingertip_left.STL"/>
      </geometry>
      <material name="">
        <color rgba="0.250980392156863 0.250980392156863 0.250980392156863 1.0"/>
      </material>
    </visual>
    <collision>
      <origin xyz="0.0 0.0 0.0" rpy="0.0 0.0 0.0"/>
      <geometry>
        <mesh filename="../meshes/link_gripper_fingertip_left.STL"/>
      </geometry>
    </collision>
  </link>
  <joint name="joint_gripper_fingertip_left" type="fixed">
    <origin xyz="0.190596948563868 -0.015 0.0" rpy="1.57079632679496 4.51275387511463e-14 2.60113659715756"/>
    <axis xyz="0.0 0.0 0.0"/>
    <parent link="link_gripper_finger_left"/>
    <child link="link_gripper_fingertip_left"/>
  </joint>
  <joint name="base_y_joint" type="fixed">
    <origin xyz="0 0 0" rpy="0.0 0.0 1.57079632679496"/>
    <axis xyz="1.0 0.0 0.0"/>
    <parent link="base_xy_link"/>
    <child link="base_theta_link"/>
    <limit effort="100.0" lower="0.0" upper="0.0" velocity="3.0"/>
  </joint>
  <joint name="base_theta_joint" type="fixed">
    <origin xyz="0.0 0.0 0.0" rpy="0.0 0.0 -1.57079632679496"/>
    <axis xyz="0.0 0.0 1.0"/>
    <parent link="base_theta_link"/>
    <child link="base_link"/>
    <limit effort="100.0" lower="0.0" upper="0.0" velocity="1.0"/>
  </joint>
  <joint name="base_x_joint" type="prismatic">
    <origin xyz="0 0 0" rpy="0.0 0.0 0.0"/>
    <axis xyz="1.0 0.0 0.0"/>
    <parent link="world"/>
    <child link="base_xy_link"/>
    <limit effort="100.0" lower="-50.0" upper="50.0" velocity="3.0"/>
  </joint>
  <link name="base_xy_link">
    <collision>
      <origin xyz="0.0 0.0 0.0" rpy="0.0 0.0 0.0"/>
      <geometry>
        <box size="0.01 0.01 0.01"/>
      </geometry>
    </collision>
  </link>
  <link name="base_theta_link">
    <collision>
      <origin xyz="0.0 0.0 0.0" rpy="0.0 0.0 0.0"/>
      <geometry>
        <box size="0.01 0.01 0.01"/>
      </geometry>
    </collision>
  </link>
  <link name="world"/>
  <link name="base_link">
    <inertial>
      <origin xyz="-0.109461304328163 -0.000741018909047708 0.0914915269429946" rpy="0.0 0.0 0.0"/>
      <mass value="10.0723782659782"/>
      <inertia ixx="0.00310580907710135" ixy="1.5182848191076e-06" ixz="0.00041690466732394" iyy="0.00433798719991832" iyz="1.33487716258445e-05" izz="0.0037204727467362"/>
    </inertial>
    <visual>
      <origin xyz="0.0 0.0 0.0" rpy="0.0 0.0 0.0"/>
      <geometry>
        <mesh filename="../meshes/base_link.STL"/>
      </geometry>
      <material name="">
        <color rgba="0.792156862745098 0.819607843137255 0.933333333333333 1.0"/>
      </material>
    </visual>
    <collision>
      <origin xyz="-0.117155 7.5e-05 0.078399" rpy="-1.570796 1.570796 0.0"/>
      <geometry>
        <box size="0.143197 0.324688 0.361202"/>
      </geometry>
    </collision>
  </link>
  <link name="link_right_wheel">
    <inertial>
      <origin xyz="1.25554620866719e-07 3.54748938447003e-07 0.0239581106165018" rpy="0.0 0.0 0.0"/>
      <mass value="0.01"/>
      <inertia ixx="0.001" ixy="0.0" ixz="0.0" iyy="0.001" iyz="0.0" izz="0.001"/>
    </inertial>
    <visual>
      <origin xyz="0.0 0.0 0.0" rpy="0.0 0.0 0.0"/>
      <geometry>
        <mesh filename="../meshes/link_right_wheel.STL"/>
      </geometry>
      <material name="">
        <color rgba="0.792156862745098 0.819607843137255 0.933333333333333 1.0"/>
      </material>
    </visual>
  </link>
  <joint name="joint_right_wheel" type="continuous">
    <origin xyz="-0.00300000000000034 -0.15765 0.0508000000000004" rpy="-1.57079632679489 -1.11022302462516e-16 7.28583859910277e-17"/>
    <axis xyz="0.0 0.0 1.0"/>
    <parent link="base_link"/>
    <child link="link_right_wheel"/>
    <dynamics damping="21.75" friction="10.48"/>
  </joint>
  <link name="link_left_wheel">
    <inertial>
      <origin xyz="1.2555462092223e-07 -3.54748938502514e-07 -0.0239581106165035" rpy="0.0 0.0 0.0"/>
      <mass value="0.01"/>
      <inertia ixx="0.001" ixy="0.0" ixz="0.0" iyy="0.001" iyz="0.0" izz="0.001"/>
    </inertial>
    <visual>
      <origin xyz="0.0 0.0 0.0" rpy="0.0 0.0 0.0"/>
      <geometry>
        <mesh filename="../meshes/link_left_wheel.STL"/>
      </geometry>
      <material name="">
        <color rgba="0.792156862745098 0.819607843137255 0.933333333333333 1.0"/>
      </material>
    </visual>
  </link>
  <joint name="joint_left_wheel" type="continuous">
    <origin xyz="-0.00300000000001899 0.15765 0.0507999999999994" rpy="-1.5707963267949 3.16227047920818e-31 7.88745438253713e-16"/>
    <axis xyz="0.0 0.0 1.0"/>
    <parent link="base_link"/>
    <child link="link_left_wheel"/>
    <dynamics damping="21.75" friction="10.48"/>
  </joint>
  <link name="caster_link">
    <inertial>
      <origin xyz="0.0 0.0 0.0" rpy="0 0 0"/>
      <mass value="0.01"/>
      <inertia ixx="0.001" ixy="0.0" ixz="0.0" iyy="0.001" iyz="0.0" izz="0.001"/>
    </inertial>
    <visual>
      <origin xyz="0.0 0.0 0.0" rpy="0.0 0.0 0.0"/>
      <geometry>
        <mesh filename="../meshes/omni_wheel_m.STL"/>
      </geometry>
      <material name="">
        <color rgba="0.792156862745098 0.819607843137255 0.933333333333333 1.0"/>
      </material>
    </visual>
  </link>
  <joint name="caster_joint" type="fixed">
    <origin xyz="-0.245 0.0 0.032" rpy="-1.5707963267948966 0.0 0.0"/>
    <axis xyz="0.0 0.0 1.0"/>
    <parent link="base_link"/>
    <child link="caster_link"/>
  </joint>
  <link name="link_mast">
    <inertial>
      <origin xyz="0.00755818572975822 0.773971284176834 0.00647313086620024" rpy="0.0 0.0 0.0"/>
      <mass value="0.749143203376401"/>
      <inertia ixx="0.0709854511954588" ixy="-0.00433428742758457" ixz="-0.000186110788697573" iyy="0.000437922053342648" iyz="-0.00288788257713431" izz="0.071104808501661"/>
    </inertial>
    <visual>
      <origin xyz="0.0 0.0 0.0" rpy="0.0 0.0 0.0"/>
      <geometry>
        <mesh filename="../meshes/link_mast.STL"/>
      </geometry>
      <material name="">
        <color rgba="0.792156862745098 0.819607843137255 0.933333333333333 1.0"/>
      </material>
    </visual>
    <collision>
      <origin xyz="-0.0 0.7075 0.0" rpy="1.570796 1.570796 -0.0"/>
      <geometry>
        <box size="0.038125 0.038125 1.285"/>
      </geometry>
    </collision>
  </link>
  <joint name="joint_mast" type="fixed">
    <origin xyz="-0.06949477028757628 0.13838980304778414 0.027045430913364362" rpy="1.5646590837134537 -0.017304958691331196 0.04825274364916361"/>
    <axis xyz="0.0 0.0 0.0"/>
    <parent link="base_link"/>
    <child link="link_mast"/>
  </joint>
  <link name="link_lift">
    <inertial>
      <origin xyz="-0.0547636346252869 0.0380939689802074 0.00933159404448308" rpy="0.0 0.0 0.0"/>
      <mass value="0.444820831236007"/>
      <inertia ixx="0.000567192946271367" ixy="-0.00024607534789508" ixz="-0.000128108442260574" iyy="0.00127108364478659" iyz="7.61916855070339e-06" izz="0.00137296635099006"/>
    </inertial>
    <visual>
      <origin xyz="0.0 0.0 0.0" rpy="0.0 0.0 0.0"/>
      <geometry>
        <mesh filename="../meshes/link_lift.STL"/>
      </geometry>
      <material name="">
        <color rgba="0.792156862745098 0.819607843137255 0.933333333333333 1.0"/>
      </material>
    </visual>
    <collision>
      <origin xyz="-0.030334 0.03951 0.026256" rpy="-2.192103 1.570796 0.0"/>
      <geometry>
        <box size="0.120261 0.137963 0.258855"/>
      </geometry>
    </collision>
  </link>
  <joint name="joint_lift" type="prismatic">
    <origin xyz="-0.0369217062323472 0.165471199999996 -0.000341653286793524" rpy="-1.57079632679552 1.5615431375292 -6.2942004366467e-13"/>
    <axis xyz="0.0 0.0 1.0"/>
    <parent link="link_mast"/>
    <child link="link_lift"/>
    <limit effort="100.0" lower="0.0" upper="1.1" velocity="1.0"/>
  </joint>
  <link name="link_arm_l4">
    <inertial>
      <origin xyz="-1.61247276464493e-06 1.54715589201215e-06 -0.0953252706040035" rpy="0.0 0.0 0.0"/>
      <mass value="0.0676525455789735"/>
      <inertia ixx="0.000122002023066796" ixy="7.29593356230121e-13" ixz="9.63170353371061e-09" iyy="0.000122002023127152" iyz="-9.24154949889042e-09" izz="1.46043439809638e-12"/>
    </inertial>
    <visual>
      <origin xyz="0.0 0.0 0.0" rpy="0.0 0.0 0.0"/>
      <geometry>
        <mesh filename="../meshes/link_arm_l4.STL"/>
      </geometry>
      <material name="">
        <color rgba="0.792156862745098 0.819607843137255 0.933333333333333 1.0"/>
      </material>
    </visual>
    <collision>
      <origin xyz="-0.0 0.0 -0.11125" rpy="-3.141593 0.0 -1.570796"/>
      <geometry>
        <box size="0.05925 0.05925 0.2225"/>
      </geometry>
    </collision>
  </link>
  <joint name="joint_arm_l4" type="fixed">
    <origin xyz="-0.25669443874094205 0.005713417002918588 0.0012296937814473496" rpy="1.5781652616599324 0.04551858006017695 -1.6181874684011688"/>
    <axis xyz="0.0 0.0 0.0"/>
    <parent link="link_lift"/>
    <child link="link_arm_l4"/>
  </joint>
  <link name="link_arm_l3">
    <inertial>
      <origin xyz="-3.34873468621488e-07 4.7411336306924e-07 -0.0974069598289041" rpy="0.0 0.0 0.0"/>
      <mass value="0.0626921047058405"/>
      <inertia ixx="0.001" ixy="0.0" ixz="0.0" iyy="0.001" iyz="0.0" izz="0.001"/>
    </inertial>
    <visual>
      <origin xyz="0.0 0.0 0.0" rpy="0.0 0.0 0.0"/>
      <geometry>
        <mesh filename="../meshes/link_arm_l3.STL"/>
      </geometry>
      <material name="">
        <color rgba="0.792156862745098 0.819607843137255 0.933333333333333 1.0"/>
      </material>
    </visual>
    <collision>
      <origin xyz="0.0 -0.0 -0.11325" rpy="0.0 -0.0 -1.570796"/>
      <geometry>
        <box size="0.05525 0.05525 0.2265"/>
      </geometry>
    </collision>
  </link>
  <joint name="joint_arm_l3" type="prismatic">
    <origin xyz="0.0 0.0 0.013" rpy="3.5742e-16 3.2123e-16 -2.4565e-16"/>
    <axis xyz="0.0 0.0 1.0"/>
    <parent link="link_arm_l4"/>
    <child link="link_arm_l3"/>
    <limit effort="100.0" lower="0.0" upper="0.13" velocity="1.0"/>
  </joint>
  <link name="link_arm_l2">
    <inertial>
      <origin xyz="-3.31043560508615e-07 3.13422303999111e-07 -0.097255883541891" rpy="0.0 0.0 0.0"/>
      <mass value="0.0569074368576238"/>
      <inertia ixx="0.001" ixy="0.0" ixz="0.0" iyy="0.001" iyz="0.0" izz="0.001"/>
    </inertial>
    <visual>
      <origin xyz="0.0 0.0 0.0" rpy="0.0 0.0 0.0"/>
      <geometry>
        <mesh filename="../meshes/link_arm_l2.STL"/>
      </geometry>
      <material name="">
        <color rgba="0.792156862745098 0.819607843137255 0.933333333333333 1.0"/>
      </material>
    </visual>
    <collision>
      <origin xyz="-0.0 -0.0 -0.11325" rpy="-3.141593 0.0 -1.570796"/>
      <geometry>
        <box size="0.05125 0.05125 0.2265"/>
      </geometry>
    </collision>
  </link>
  <joint name="joint_arm_l2" type="prismatic">
    <origin xyz="0.0 0.0 0.013" rpy="2.91385731014123e-16 4.44300759504684e-17 3.25691080516352e-16"/>
    <axis xyz="0.0 0.0 1.0"/>
    <parent link="link_arm_l3"/>
    <child link="link_arm_l2"/>
    <limit effort="100.0" lower="0.0" upper="0.13" velocity="1.0"/>
  </joint>
  <link name="link_arm_l1">
    <inertial>
      <origin xyz="-3.36876635420591e-07 3.05876091066803e-07 -0.0969117032232756" rpy="0.0 0.0 0.0"/>
      <mass value="0.0511763619538321"/>
      <inertia ixx="0.001" ixy="0.0" ixz="0.0" iyy="0.001" iyz="0.0" izz="0.001"/>
    </inertial>
    <visual>
      <origin xyz="0.0 0.0 0.0" rpy="0.0 0.0 0.0"/>
      <geometry>
        <mesh filename="../meshes/link_arm_l1.STL"/>
      </geometry>
      <material name="">
        <color rgba="0.792156862745098 0.819607843137255 0.933333333333333 1.0"/>
      </material>
    </visual>
    <collision>
      <origin xyz="0.0 -0.0 -0.11325" rpy="-3.141593 0.0 -1.570796"/>
      <geometry>
        <box size="0.04725 0.04725 0.2265"/>
      </geometry>
    </collision>
  </link>
  <joint name="joint_arm_l1" type="prismatic">
    <origin xyz="0.0 0.0 0.013" rpy="7.41596560408007e-17 1.33876788296791e-16 -2.44545873596083e-16"/>
    <axis xyz="0.0 0.0 1.0"/>
    <parent link="link_arm_l2"/>
    <child link="link_arm_l1"/>
    <limit effort="100.0" lower="0.0" upper="0.13" velocity="1.0"/>
  </joint>
  <link name="link_arm_l0">
    <inertial>
      <origin xyz="0.0230715049668191 -0.00195115833662818 -0.0360646347160285" rpy="0.0 0.0 0.0"/>
      <mass value="0.101241250325294"/>
      <inertia ixx="0.001" ixy="0.0" ixz="0.0" iyy="0.001" iyz="0.0" izz="0.001"/>
    </inertial>
    <visual>
      <origin xyz="0.0 0.0 0.0" rpy="0.0 0.0 0.0"/>
      <geometry>
        <mesh filename="../meshes/link_arm_l0.STL"/>
      </geometry>
      <material name="">
        <color rgba="0.792156862745098 0.819607843137255 0.933333333333333 1.0"/>
      </material>
    </visual>
    <collision>
      <origin xyz="0.041161 -0.000358 -0.0865" rpy="-3.141593 0.0 -1.570796"/>
      <geometry>
        <box size="0.059285 0.127573 0.2265"/>
      </geometry>
    </collision>
  </link>
  <joint name="joint_arm_l0" type="prismatic">
    <origin xyz="0.0 0.0 -0.0137499999999938" rpy="-3.05317390622457e-16 -4.23236224076729e-16 -2.68425135229209e-17"/>
    <axis xyz="0.0 0.0 1.0"/>
    <parent link="link_arm_l1"/>
    <child link="link_arm_l0"/>
    <limit effort="100.0" lower="0.0" upper="0.13" velocity="1.0"/>
  </joint>
  <link name="link_wrist_yaw">
    <inertial>
      <origin xyz="-8.02795716750571e-06 1.93811447768422e-05 0.018946700595851" rpy="0.0 0.0 0.0"/>
      <mass value="0.0405398981326229"/>
      <inertia ixx="0.001" ixy="0.0" ixz="0.0" iyy="0.001" iyz="0.0" izz="0.001"/>
    </inertial>
    <visual>
      <origin xyz="0.0 0.0 0.0" rpy="0.0 0.0 0.0"/>
      <geometry>
        <mesh filename="../meshes/link_wrist_yaw.STL"/>
      </geometry>
      <material name="">
        <color rgba="0.792156862745098 0.819607843137255 0.933333333333333 1.0"/>
      </material>
    </visual>
    <collision>
      <origin xyz="-2.2e-05 -1e-05 -0.019" rpy="-3.141593 0.0 0.432976"/>
      <geometry>
        <box size="0.029951 0.029976 0.038"/>
      </geometry>
    </collision>
  </link>
  <joint name="joint_wrist_yaw" type="revolute">
    <origin xyz="0.083 -0.03075 0.0" rpy="1.5708 4.2595e-14 2.6415e-15"/>
    <axis xyz="0.0 0.0 -1.0"/>
    <parent link="link_arm_l0"/>
    <child link="link_wrist_yaw"/>
    <limit effort="100.0" lower="-1.75" upper="4.0" velocity="1.0"/>
  </joint>
  <link name="link_head">
    <inertial>
      <origin xyz="0.0372933550588956 0.045509432985552 0.0281136801213409" rpy="0.0 0.0 0.0"/>
      <mass value="0.129454717596498"/>
      <inertia ixx="0.001" ixy="0.0" ixz="0.0" iyy="0.001" iyz="0.0" izz="0.001"/>
    </inertial>
    <visual>
      <origin xyz="0.0 0.0 0.0" rpy="0.0 0.0 0.0"/>
      <geometry>
        <mesh filename="../meshes/link_head.STL"/>
      </geometry>
      <material name="">
        <color rgba="0.792156862745098 0.819607843137255 0.933333333333333 1.0"/>
      </material>
    </visual>
    <collision>
      <origin xyz="0.061219 0.028457 0.028216" rpy="0.158839 1.570692 0.18178"/>
      <geometry>
        <box size="0.056453 0.131612 0.19515"/>
      </geometry>
    </collision>
  </link>
  <joint name="joint_head" type="fixed">
    <origin xyz="0.0 1.33 0.0" rpy="1.5708 -1.5615 3.1416"/>
    <axis xyz="0.0 0.0 0.0"/>
    <parent link="link_mast"/>
    <child link="link_head"/>
  </joint>
  <link name="link_head_pan">
    <inertial>
      <origin xyz="-0.00116200255310878 0.0130365621706306 0.00137629842298681" rpy="0.0 0.0 0.0"/>
      <mass value="0.035858341182617"/>
      <inertia ixx="0.001" ixy="0.0" ixz="0.0" iyy="0.001" iyz="0.0" izz="0.001"/>
    </inertial>
    <visual>
      <origin xyz="0.0 0.0 0.0" rpy="0.0 0.0 0.0"/>
      <geometry>
        <mesh filename="../meshes/link_head_pan.STL"/>
      </geometry>
      <material name="">
        <color rgba="0.792156862745098 0.819607843137255 0.933333333333333 1.0"/>
      </material>
    </visual>
    <collision>
      <origin xyz="0.000813 0.017168 -0.011469" rpy="0.53407 0.004098 -0.0"/>
      <geometry>
        <box size="0.043969 0.048193 0.122235"/>
      </geometry>
    </collision>
  </link>
  <joint name="joint_head_pan" type="revolute">
    <origin xyz="0.14394738959044898 0.0689269242761915 -0.003064182445303723" rpy="0.008083283195200545 0.000583944763831834 1.620778470351339"/>
    <axis xyz="0.0 0.0 1.0"/>
    <parent link="link_head"/>
    <child link="link_head_pan"/>
    <limit effort="100.0" lower="-3.9" upper="1.5" velocity="1.0"/>
  </joint>
  <link name="link_head_tilt">
    <inertial>
      <origin xyz="0.00920211049011871 -0.0279724762416447 0.0306580436227023" rpy="0.0 0.0 0.0"/>
      <mass value="0.0701242408063442"/>
      <inertia ixx="0.001" ixy="0.0" ixz="0.0" iyy="0.001" iyz="0.0" izz="0.001"/>
    </inertial>
    <visual>
      <origin xyz="0.0 0.0 0.0" rpy="0.0 0.0 0.0"/>
      <geometry>
        <mesh filename="../meshes/link_head_tilt.STL"/>
      </geometry>
      <material name="">
        <color rgba="0.792156862745098 0.819607843137255 0.933333333333333 1.0"/>
      </material>
    </visual>
    <collision>
      <origin xyz="0.010814 -0.023473 0.030498" rpy="1.562383 1.569947 -0.008414"/>
      <geometry>
        <box size="0.061014 0.068029 0.120844"/>
      </geometry>
    </collision>
  </link>
  <joint name="joint_head_tilt" type="revolute">
    <origin xyz="-0.0038009318349181698 0.027661869381952295 -0.06046636278717248" rpy="1.583686486584009 0.038258710433179965 0.07682454066916562"/>
    <axis xyz="0.0 0.0 1.0"/>
    <parent link="link_head_pan"/>
    <child link="link_head_tilt"/>
    <limit effort="100.0" lower="-1.53" upper="0.79" velocity="1.0"/>
  </joint>
  <link name="link_aruco_right_base">
    <inertial>
      <origin xyz="0.0 0.0 -5.00000000014378e-07" rpy="0.0 0.0 0.0"/>
      <mass value="3.59999999990368e-06"/>
      <inertia ixx="0.0" ixy="0.0" ixz="0.0" iyy="0.0" iyz="0.0" izz="0.0"/>
    </inertial>
    <visual>
      <origin xyz="0.0 0.0 0.0" rpy="0.0 0.0 0.0"/>
      <geometry>
        <mesh filename="../meshes/link_aruco_right_base.STL"/>
      </geometry>
      <material name="">
        <color rgba="0.792156862745098 0.819607843137255 0.933333333333333 1.0"/>
      </material>
    </visual>
  </link>
  <joint name="joint_aruco_right_base" type="fixed">
    <origin xyz="-0.00500000000000014 -0.1304972 0.1597482" rpy="0.0 0.0 -1.5707963267949"/>
    <axis xyz="0.0 0.0 0.0"/>
    <parent link="base_link"/>
    <child link="link_aruco_right_base"/>
  </joint>
  <link name="link_aruco_left_base">
    <inertial>
      <origin xyz="0.0 0.0 -5.00000000014378e-07" rpy="0.0 0.0 0.0"/>
      <mass value="3.59999999990368e-06"/>
      <inertia ixx="0.0" ixy="0.0" ixz="0.0" iyy="0.0" iyz="0.0" izz="0.0"/>
    </inertial>
    <visual>
      <origin xyz="0.0 0.0 0.0" rpy="0.0 0.0 0.0"/>
      <geometry>
        <mesh filename="../meshes/link_aruco_left_base.STL"/>
      </geometry>
      <material name="">
        <color rgba="0.792156862745098 0.819607843137255 0.933333333333333 1.0"/>
      </material>
    </visual>
  </link>
  <joint name="joint_aruco_left_base" type="fixed">
    <origin xyz="-0.00500000000000014 0.1304972 0.1597482" rpy="0.0 0.0 -1.5707963267949"/>
    <axis xyz="0.0 0.0 0.0"/>
    <parent link="base_link"/>
    <child link="link_aruco_left_base"/>
  </joint>
  <link name="link_aruco_shoulder">
    <inertial>
      <origin xyz="-2.77555756156289e-17 2.56739074444567e-16 -0.000125000000000042" rpy="0.0 0.0 0.0"/>
      <mass value="0.0"/>
      <inertia ixx="0.0" ixy="0.0" ixz="0.0" iyy="0.0" iyz="0.0" izz="0.0"/>
    </inertial>
    <visual>
      <origin xyz="0.0 0.0 0.0" rpy="0.0 0.0 0.0"/>
      <geometry>
        <mesh filename="../meshes/link_aruco_shoulder.STL"/>
      </geometry>
      <material name="">
        <color rgba="0.792156862745098 0.819607843137255 0.933333333333333 1.0"/>
      </material>
    </visual>
  </link>
  <joint name="joint_aruco_shoulder" type="fixed">
    <origin xyz="-0.0133768876375287 0.0558540528812078 0.0861368272417975" rpy="-1.53998860117704e-29 3.55962409571165e-15 0.0"/>
    <axis xyz="0.0 0.0 0.0"/>
    <parent link="link_lift"/>
    <child link="link_aruco_shoulder"/>
  </joint>
  <link name="link_aruco_top_wrist">
    <inertial>
      <origin xyz="1.11022302462516e-16 3.05311331771918e-16 -0.00012499999999821" rpy="0.0 0.0 0.0"/>
      <mass value="0.0"/>
      <inertia ixx="0.0" ixy="0.0" ixz="0.0" iyy="0.0" iyz="0.0" izz="0.0"/>
    </inertial>
    <visual>
      <origin xyz="0.0 0.0 0.0" rpy="0.0 0.0 0.0"/>
      <geometry>
        <mesh filename="../meshes/link_aruco_top_wrist.STL"/>
      </geometry>
      <material name="">
        <color rgba="0.792156862745098 0.819607843137255 0.933333333333333 1.0"/>
      </material>
    </visual>
    <collision>
      <origin xyz="0.0 0.0 0.0" rpy="0.0 0.0 0.0"/>
      <geometry>
        <mesh filename="../meshes/link_aruco_top_wrist.STL"/>
      </geometry>
    </collision>
  </link>
  <joint name="joint_aruco_top_wrist" type="fixed">
    <origin xyz="0.0472500000000019 0.0292850000000015 0.0" rpy="1.5707963267949 -8.03728587323464e-15 3.14159265358979"/>
    <axis xyz="0.0 0.0 0.0"/>
    <parent link="link_arm_l0"/>
    <child link="link_aruco_top_wrist"/>
  </joint>
  <link name="link_aruco_inner_wrist">
    <inertial>
      <origin xyz="8.32667268468867e-17 1.77635683940025e-15 -0.000125000000000264" rpy="0.0 0.0 0.0"/>
      <mass value="0.0"/>
      <inertia ixx="0.0" ixy="0.0" ixz="0.0" iyy="0.0" iyz="0.0" izz="0.0"/>
    </inertial>
    <visual>
      <origin xyz="0.0 0.0 0.0" rpy="0.0 0.0 0.0"/>
      <geometry>
        <mesh filename="../meshes/link_aruco_inner_wrist.STL"/>
      </geometry>
      <material name="">
        <color rgba="0.792156862745098 0.819607843137255 0.933333333333333 1.0"/>
      </material>
    </visual>
  </link>
  <joint name="joint_aruco_inner_wrist" type="fixed">
    <origin xyz="0.0472499999999947 -0.0119000000000034 -0.0272499999991938" rpy="3.14159265358979 4.23377442363088e-14 3.14159265358979"/>
    <axis xyz="0.0 0.0 0.0"/>
    <parent link="link_arm_l0"/>
    <child link="link_aruco_inner_wrist"/>
  </joint>
  <material name="aluminum">
    <color rgba="0.5 0.5 0.5 1.0"/>
  </material>
  <material name="plastic">
    <color rgba="0.1 0.1 0.1 1.0"/>
  </material>
  <joint name="camera_joint" type="fixed">
    <origin xyz="0.025070381118864622 -0.012287278361953074 0.017905872362600883" rpy="0.0027184810411859444 0.001558563349419062 -0.04777120277132254"/>
    <parent link="link_head_tilt"/>
    <child link="camera_bottom_screw_frame"/>
  </joint>
  <link name="camera_bottom_screw_frame"/>
  <joint name="camera_link_joint" type="fixed">
    <origin xyz="0.010600000000000002 0.0175 0.0125" rpy="0.0 0.0 0.0"/>
    <parent link="camera_bottom_screw_frame"/>
    <child link="camera_link"/>
  </joint>
  <link name="camera_link">
    <inertial>
      <origin xyz="0.0 0.0 0.0" rpy="0 0 0"/>
      <mass value="0.072"/>
      <inertia ixx="0.003881243" ixy="0.0" ixz="0.0" iyy="0.00049894" iyz="0.0" izz="0.003879257"/>
    </inertial>
    <visual>
      <origin xyz="0.0043 -0.0175 0.0" rpy="1.5707963267948966 0.0 1.5707963267948966"/>
      <geometry>
        <mesh filename="../meshes/realsense2/d435.dae"/>
      </geometry>
    </visual>
    <collision>
      <origin xyz="0.0 -0.0175 0.0" rpy="0.0 0.0 0.0"/>
      <geometry>
        <box size="0.02505 0.09 0.025"/>
      </geometry>
    </collision>
  </link>
  <joint name="camera_depth_joint" type="fixed">
    <origin xyz="0.0 0.0 0.0" rpy="0.0 0.0 0.0"/>
    <parent link="camera_link"/>
    <child link="camera_depth_frame"/>
  </joint>
  <link name="camera_depth_frame"/>
  <joint name="camera_depth_optical_joint" type="fixed">
    <origin xyz="0.0 0.0 0.0" rpy="-1.5707963267948966 0.0 -1.5707963267948966"/>
    <parent link="camera_depth_frame"/>
    <child link="camera_depth_optical_frame"/>
  </joint>
  <link name="camera_depth_optical_frame"/>
  <joint name="camera_infra1_joint" type="fixed">
    <origin xyz="0.0 0.0 0.0" rpy="0.0 0.0 0.0"/>
    <parent link="camera_link"/>
    <child link="camera_infra1_frame"/>
  </joint>
  <link name="camera_infra1_frame"/>
  <joint name="camera_infra1_optical_joint" type="fixed">
    <origin xyz="0.0 0.0 0.0" rpy="-1.5707963267948966 0.0 -1.5707963267948966"/>
    <parent link="camera_infra1_frame"/>
    <child link="camera_infra1_optical_frame"/>
  </joint>
  <link name="camera_infra1_optical_frame"/>
  <joint name="camera_infra2_joint" type="fixed">
    <origin xyz="0.0 -0.05 0.0" rpy="0.0 0.0 0.0"/>
    <parent link="camera_link"/>
    <child link="camera_infra2_frame"/>
  </joint>
  <link name="camera_infra2_frame"/>
  <joint name="camera_infra2_optical_joint" type="fixed">
    <origin xyz="0.0 0.0 0.0" rpy="-1.5707963267948966 0.0 -1.5707963267948966"/>
    <parent link="camera_infra2_frame"/>
    <child link="camera_infra2_optical_frame"/>
  </joint>
  <link name="camera_infra2_optical_frame"/>
  <joint name="camera_color_joint" type="fixed">
    <origin xyz="0.0 0.015 0.0" rpy="0.0 0.0 0.0"/>
    <parent link="camera_link"/>
    <child link="camera_color_frame"/>
  </joint>
  <link name="camera_color_frame"/>
  <joint name="camera_color_optical_joint" type="fixed">
    <origin xyz="0.0 0.0 0.0" rpy="-1.5707963267948966 0.0 -1.5707963267948966"/>
    <parent link="camera_color_frame"/>
    <child link="camera_color_optical_frame"/>
  </joint>
  <link name="camera_color_optical_frame"/>
  <link name="camera_accel_frame"/>
  <link name="camera_accel_optical_frame"/>
  <link name="camera_gyro_frame"/>
  <link name="camera_gyro_optical_frame"/>
  <joint name="camera_accel_joint" type="fixed">
    <origin xyz="-0.01174 -0.00552 0.0051" rpy="0.0 0.0 0.0"/>
    <parent link="camera_link"/>
    <child link="camera_accel_frame"/>
  </joint>
  <joint name="camera_accel_optical_joint" type="fixed">
    <origin xyz="0.0 0.0 0.0" rpy="-1.5707963267948966 0.0 -1.5707963267948966"/>
    <parent link="camera_accel_frame"/>
    <child link="camera_accel_optical_frame"/>
  </joint>
  <joint name="camera_gyro_joint" type="fixed">
    <origin xyz="-0.01174 -0.00552 0.0051" rpy="0.0 0.0 0.0"/>
    <parent link="camera_link"/>
    <child link="camera_gyro_frame"/>
  </joint>
  <joint name="camera_gyro_optical_joint" type="fixed">
    <origin xyz="0.0 0.0 0.0" rpy="-1.5707963267948966 0.0 -1.5707963267948966"/>
    <parent link="camera_gyro_frame"/>
    <child link="camera_gyro_optical_frame"/>
  </joint>
  <link name="laser">
    <inertial>
      <origin xyz="0.0 0.0 -0.000755956127492408" rpy="0.0 0.0 0.0"/>
      <mass value="0.0749979022894495"/>
      <inertia ixx="0.0" ixy="0.0" ixz="0.0" iyy="0.0" iyz="0.0" izz="0.0"/>
    </inertial>
    <visual>
      <origin xyz="0.0 0.0 0.0" rpy="0.0 0.0 0.0"/>
      <geometry>
        <mesh filename="../meshes/laser.STL"/>
      </geometry>
      <material name="">
        <color rgba="0.250980392156863 0.250980392156863 0.250980392156863 1.0"/>
      </material>
    </visual>
    <collision>
      <origin xyz="-0.00075 0.0 0.0" rpy="-1.570796 1.570796 1.570796"/>
      <geometry>
        <box size="0.0195 0.06994 0.06994"/>
      </geometry>
    </collision>
  </link>
  <joint name="joint_laser" type="fixed">
    <origin xyz="0.000502800000000914 0.0 0.1664" rpy="0.0 0.0 -3.14159265358979"/>
    <axis xyz="0.0 0.0 0.0"/>
    <parent link="base_link"/>
    <child link="laser"/>
  </joint>
  <link name="respeaker_base">
    <inertial>
      <origin xyz="-0.00078082896792734 0.00765742173486017 -0.0042488298301937" rpy="0.0 0.0 0.0"/>
      <mass value="0.00969129410417277"/>
      <inertia ixx="8.95656300428405e-07" ixy="2.67330745809535e-08" ixz="-3.84519793580934e-08" iyy="4.0421099617056e-07" iyz="3.15533542838673e-07" izz="7.08282597118018e-07"/>
    </inertial>
    <visual>
      <origin xyz="0.0 0.0 0.0" rpy="0.0 0.0 0.0"/>
      <geometry>
        <mesh filename="../meshes/link_respeaker.STL"/>
      </geometry>
      <material name="">
        <color rgba="0.792156862745098 0.819607843137255 0.933333333333333 1.0"/>
      </material>
    </visual>
    <collision>
      <origin xyz="-0.000138 0.006371 -0.017378" rpy="0.29012 1.487727 1.744709"/>
      <geometry>
        <box size="0.042669 0.070906 0.079812"/>
      </geometry>
    </collision>
  </link>
  <joint name="joint_respeaker" type="fixed">
    <origin xyz="1.09074743137871e-05 1.36992 0.00303572796911382" rpy="1.57079632679553 0.0 3.14159265358916"/>
    <axis xyz="0.0 0.0 0.0"/>
    <parent link="link_mast"/>
    <child link="respeaker_base"/>
  </joint>
</robot>